INFO - (10/15/2024 10:30:26 PM): [PID: 5716] Starting the script (Line: 18 [main.py])
INFO - (10/15/2024 10:30:56 PM): [PID: 5833] Starting the script (Line: 18 [main.py])
ERROR - (10/15/2024 10:30:56 PM): [PID: 5833] Uncaught exception (Line: 77 [logconfig.py])
Traceback (most recent call last):
  File "/home/shazib/Desktop/linux/test/lib/python3.10/site-packages/urllib3/connection.py", line 174, in _new_conn
    conn = connection.create_connection(
  File "/home/shazib/Desktop/linux/test/lib/python3.10/site-packages/urllib3/util/connection.py", line 72, in create_connection
    for res in socket.getaddrinfo(host, port, family, socket.SOCK_STREAM):
  File "/usr/lib/python3.10/socket.py", line 955, in getaddrinfo
    for res in _socket.getaddrinfo(host, port, family, type, proto, flags):
socket.gaierror: [Errno -2] Name or service not known

During handling of the above exception, another exception occurred:

Traceback (most recent call last):
  File "/home/shazib/Desktop/linux/test/lib/python3.10/site-packages/urllib3/connectionpool.py", line 715, in urlopen
    httplib_response = self._make_request(
  File "/home/shazib/Desktop/linux/test/lib/python3.10/site-packages/urllib3/connectionpool.py", line 404, in _make_request
    self._validate_conn(conn)
  File "/home/shazib/Desktop/linux/test/lib/python3.10/site-packages/urllib3/connectionpool.py", line 1058, in _validate_conn
    conn.connect()
  File "/home/shazib/Desktop/linux/test/lib/python3.10/site-packages/urllib3/connection.py", line 363, in connect
    self.sock = conn = self._new_conn()
  File "/home/shazib/Desktop/linux/test/lib/python3.10/site-packages/urllib3/connection.py", line 186, in _new_conn
    raise NewConnectionError(
urllib3.exceptions.NewConnectionError: <urllib3.connection.HTTPSConnection object at 0x7671ba00ab60>: Failed to establish a new connection: [Errno -2] Name or service not known

During handling of the above exception, another exception occurred:

Traceback (most recent call last):
  File "/home/shazib/Desktop/linux/test/lib/python3.10/site-packages/requests/adapters.py", line 486, in send
    resp = conn.urlopen(
  File "/home/shazib/Desktop/linux/test/lib/python3.10/site-packages/urllib3/connectionpool.py", line 799, in urlopen
    retries = retries.increment(
  File "/home/shazib/Desktop/linux/test/lib/python3.10/site-packages/urllib3/util/retry.py", line 592, in increment
    raise MaxRetryError(_pool, url, error or ResponseError(cause))
urllib3.exceptions.MaxRetryError: HTTPSConnectionPool(host='next-episode.net', port=443): Max retries exceeded with url: /userlogin (Caused by NewConnectionError('<urllib3.connection.HTTPSConnection object at 0x7671ba00ab60>: Failed to establish a new connection: [Errno -2] Name or service not known'))

During handling of the above exception, another exception occurred:

Traceback (most recent call last):
  File "/home/shazib/Desktop/Folder/python/Notify_about_series/main.py", line 21, in <module>
    s = login(USERNAME,PASSWORD,LOGIN_URL)
  File "/home/shazib/Desktop/Folder/python/Notify_about_series/utility/login.py", line 11, in login
    s.post(login_url,data=login_payload)
  File "/home/shazib/Desktop/linux/test/lib/python3.10/site-packages/requests/sessions.py", line 637, in post
    return self.request("POST", url, data=data, json=json, **kwargs)
  File "/home/shazib/Desktop/linux/test/lib/python3.10/site-packages/requests/sessions.py", line 589, in request
    resp = self.send(prep, **send_kwargs)
  File "/home/shazib/Desktop/linux/test/lib/python3.10/site-packages/requests/sessions.py", line 703, in send
    r = adapter.send(request, **kwargs)
  File "/home/shazib/Desktop/linux/test/lib/python3.10/site-packages/requests/adapters.py", line 519, in send
    raise ConnectionError(e, request=request)
requests.exceptions.ConnectionError: HTTPSConnectionPool(host='next-episode.net', port=443): Max retries exceeded with url: /userlogin (Caused by NewConnectionError('<urllib3.connection.HTTPSConnection object at 0x7671ba00ab60>: Failed to establish a new connection: [Errno -2] Name or service not known'))
INFO - (10/15/2024 10:35:04 PM): [PID: 7245] Starting the script (Line: 18 [main.py])
INFO - (10/15/2024 10:51:02 PM): [PID: 4097] Starting the script (Line: 18 [main.py])
INFO - (10/15/2024 10:51:02 PM): [PID: 4097] Cleaning up the images directory (Line: 17 [clean_up.py])
INFO - (10/15/2024 10:51:21 PM): [PID: 4137] Starting the script (Line: 18 [main.py])
INFO - (10/15/2024 10:51:21 PM): [PID: 4137] Cleaning up the images directory (Line: 17 [clean_up.py])
INFO - (10/15/2024 10:51:42 PM): [PID: 4205] Starting the script (Line: 18 [main.py])
INFO - (10/15/2024 10:51:42 PM): [PID: 4205] Cleaning up the images directory (Line: 17 [clean_up.py])
INFO - (10/15/2024 10:54:14 PM): [PID: 4375] Starting the script (Line: 18 [main.py])
INFO - (10/15/2024 10:54:14 PM): [PID: 4375] Cleaning up the images directory (Line: 17 [clean_up.py])
INFO - (10/15/2024 11:00:19 PM): [PID: 3097] Starting the script (Line: 18 [main.py])
INFO - (10/15/2024 11:00:19 PM): [PID: 3097] Cleaning up the images directory (Line: 17 [clean_up.py])
INFO - (10/15/2024 11:00:22 PM): [PID: 3097] No series found for today (Line: 34 [main.py])
INFO - (10/15/2024 11:00:22 PM): [PID: 3097] Script completed (Line: 35 [main.py])
